Workbook

Sheet 01_Resumen_Ejecutivo
A1: Reporte de Diagnóstico Técnico | Zenith GBV
A3: Nombre de la Empresa | B3: ='02_Variables_Entrada'!C4 -> Empresa Demo Zenith GBV
A4: Fecha | B4: ='02_Variables_Entrada'!C5 -> 46155
A5: Folio | B5: ='02_Variables_Entrada'!C6 -> ZGBV-0001
A7: Score Global | B7: EVA Actual | C7: EVA Proyectado | D7: ROIC | E7: WACC | F7: Veredicto
A8: =MAX(0,MIN(100,50+IF('03_Motor_Calculos'!D30>0,20,-20)+IF('03_Motor_Calculos'!D28>'03_Motor_Calculos'!D26,15,-15)+IF('03_Motor_Calculos'!D50>=1.2,10,-10)+IF('03_Motor_Calculos'!D45>2.9,5,IF('03_Motor_Calculos'!D45>=1.23,0,-5)))) -> 25 | B8: ='03_Motor_Calculos'!D30 -> -18919.718 | C8: ='03_Motor_Calculos'!D31 -> -20811.69 | D8: ='03_Motor_Calculos'!D28 -> 0.14528302 | E8: ='03_Motor_Calculos'!D26 -> 0.15242254 | F8: =IF(B8>0,IF(D8>E8,"Crea valor económico","Crea EVA pero revisar spread ROIC-WACC"),"Destruye valor económico") -> Destruye valor económico
A11: Semáforo Financiero
A12: Pilar | B12: Indicador Base | C12: Resultado | D12: Semáforo
A13: Rentabilidad | B13: EVA > 0 y ROIC > WACC | C13: ="EVA: "&TEXT(B8,"$#,##0;($#,##0);-")&" | Spread: "&TEXT(D8-E8,"0.00%") -> EVA: ($18,920) | Spread: -0.71% | D13: =IF(AND(B8>0,D8>E8),"Verde",IF(OR(B8>0,D8>E8),"Amarillo","Rojo")) -> Rojo
A14: Liquidez | B14: Razón Corriente >= 1.20 y CCC controlado | C14: ="Razón Corriente: "&TEXT('03_Motor_Calculos'!D50,"0.00")&" | CCC: "&TEXT('03_Motor_Calculos'!D55,"0.0")&" días" -> Razón Corriente: 1.82 | CCC: 77.9 días | D14: =IF('03_Motor_Calculos'!D50>=1.2,"Verde",IF('03_Motor_Calculos'!D50>=1,"Amarillo","Rojo")) -> Verde
A15: Estructura | B15: Z-Score Altman | C15: ="Z-Score: "&TEXT('03_Motor_Calculos'!D45,"0.00")&" | "&'03_Motor_Calculos'!D46 -> Z-Score: 2.55 | Zona gris | D15: =IF('03_Motor_Calculos'!D45>2.9,"Verde",IF('03_Motor_Calculos'!D45>=1.23,"Amarillo","Rojo")) -> Amarillo
A18: Notas de uso
A19: Esta plantilla separa datos crudos, motor de cálculo y estrategia. Los valores en azul/amarillo son supuestos editables; las celdas con fórmulas muestran la trazabilidad de EVA, ROIC, WACC, Z-Score y liquidez. Reemplace los datos de ejemplo en la hoja 02_Variables_Entrada para generar un diagnóstico específico.

Sheet 02_Variables_Entrada
A1: 02_Variables_Entrada | Datos crudos y supuestos editables
A3: Categoría | B3: Variable | C3: Valor | D3: Fuente
A4: Identificación | B4: Nombre de la Empresa | C4: Empresa Demo Zenith GBV | D4: Captura consultor / CRM
A5: Identificación | B5: Fecha del Reporte | C5: 46155 | D5: Fecha de generación del diagnóstico
A6: Identificación | B6: Folio | C6: ZGBV-0001 | D6: Sistema Zenith GBV
A7: Estado de Resultados | B7: Ventas | C7: 5000000 | D7: Estado de resultados / últimos 12 meses
A8: Estado de Resultados | B8: COGS / Costo de Ventas | C8: 3000000 | D8: Estado de resultados / últimos 12 meses
A9: Estado de Resultados | B9: Gastos Operativos | C9: 1200000 | D9: Estado de resultados / últimos 12 meses
A10: Estado de Resultados | B10: Depreciación y Amortización | C10: 250000 | D10: Estado de resultados / últimos 12 meses
A11: Estado de Resultados | B11: CxC Promedio | C11: 650000 | D11: Balance inicial/final o promedio mensual
A12: Estado de Resultados | B12: Inventario Promedio | C12: 750000 | D12: Balance inicial/final o promedio mensual
A13: Estado de Resultados | B13: CxP Promedio | C13: 500000 | D13: Balance inicial/final o promedio mensual
A14: Balance General | B14: Caja y Bancos | C14: 400000 | D14: Balance general
A15: Balance General | B15: Cuentas por Cobrar | C15: 650000 | D15: Balance general
A16: Balance General | B16: Inventarios | C16: 750000 | D16: Balance general
A17: Balance General | B17: Otros Activos Corrientes Operativos | C17: 200000 | D17: Balance general
A18: Balance General | B18: Activos Fijos Netos | C18: 1800000 | D18: Balance general
... A32: Parámetros Macroeconómicos | B32: Factor Mejora EVA Proyectado | C32: 0.1 | D32: Supuesto de plan de acción / escenario base

Sheet 03_Motor_Calculos
A1: 03_Motor_Calculos | Trazabilidad matemática del diagnóstico EVA
A3: Concepto | B3: Fórmula/Procedimiento | C3: Variables Involucradas | D3: Resultado
A4: 1. Cálculo de NOPAT
A5: Ventas | B5: = Ventas | C5: 02_Variables_Entrada!C7 | D5: ='02_Variables_Entrada'!C7 -> 5000000
A6: COGS / Costo de Ventas | B6: = COGS | C6: 02_Variables_Entrada!C8 | D6: ='02_Variables_Entrada'!C8 -> 3000000
A7: Gastos Operativos | B7: = Gastos Operativos | C7: 02_Variables_Entrada!C9 | D7: ='02_Variables_Entrada'!C9 -> 1200000
A8: EBITDA | B8: = Ventas - COGS - Gastos Operativos | C8: Ventas, COGS, Gastos Operativos | D8: =D5-D6-D7 -> 800000
A9: Depreciación y Amortización | B9: = Depreciación y Amortización | C9: 02_Variables_Entrada!C10 | D9: ='02_Variables_Entrada'!C10 -> 250000
A10: EBIT | B10: = EBITDA - Depreciación y Amortización | C10: EBITDA, Depreciación | D10: =D8-D9 -> 550000
A11: Impuestos Operativos | B11: = EBIT x Tasa ISR | C11: EBIT, Tasa ISR | D11: =D10*'02_Variables_Entrada'!C30 -> 165000
A12: NOPAT | B12: = EBIT - Impuestos Operativos | C12: EBIT, Impuestos Operativos | D12: =D10-D11 -> 385000
A13: 2. Cálculo de Capital Invertido
A14: Activos Corrientes Operativos | B14: = CxC + Inventarios + Otros Activos Corrientes Operativos | C14: Cuentas por Cobrar, Inventarios, Otros Activos Corrientes | D14: ='02_Variables_Entrada'!C15+'02_Variables_Entrada'!C16+'02_Variables_Entrada'!C17 -> 1600000
A15: Activos Fijos Netos | B15: = Activos Fijos Netos | C15: 02_Variables_Entrada!C23 | D15: ='02_Variables_Entrada'!C18 -> 1800000
A16: Pasivos Operativos sin Costo | B16: = Proveedores/CxP + Otros Pasivos Operativos sin Costo | C16: Proveedores, Otros Pasivos Operativos | D16: ='02_Variables_Entrada'!C19+'02_Variables_Entrada'!C22 -> 750000
A17: Capital Invertido | B17: = Activos Corrientes Operativos + Activos Fijos Netos - Pasivos Operativos sin Costo | C17: AON, AFN, Pasivos Operativos | D17: =D14+D15-D16 -> 2650000
A18: 3. Cálculo de WACC
A19: Deuda Total con Costo | B19: = Deuda CP + Deuda LP | C19: Deuda Corto Plazo, Deuda Largo Plazo | D19: ='02_Variables_Entrada'!C20+'02_Variables_Entrada'!C21 -> 1250000
A20: Capital Contable | B20: = Capital Contable | C20: 02_Variables_Entrada!C28 | D20: ='02_Variables_Entrada'!C23 -> 2300000
A21: Costo de Deuda Kd antes de ISR | B21: = Tasa de interés promedio de la deuda | C21: Tasa Kd | D21: ='02_Variables_Entrada'!C31 -> 0.14
A22: Costo de Deuda Kd después de ISR | B22: = Kd x (1 - Tasa ISR) | C22: Kd, Tasa ISR | D22: =D21*(1-'02_Variables_Entrada'!C30) -> 0.098
A23: Costo de Capital Ke CAPM ajustado | B23: = Rf + Beta x Prima de Mercado + Prima de Riesgo PyME | C23: Rf, Beta, Prima Mercado, Prima PyME | D23: ='02_Variables_Entrada'!C25+('02_Variables_Entrada'!C27*'02_Variables_Entrada'!C26)+'02_Variables_Entrada'!C28 -> 0.182
A24: Peso de Deuda | B24: = Deuda / (Deuda + Capital) | C24: Deuda Total, Capital Contable | D24: =D19/(D19+D20) -> 0.35211268
A25: Peso de Capital | B25: = Capital / (Deuda + Capital) | C25: Deuda Total, Capital Contable | D25: =D20/(D19+D20) -> 0.64788732
A26: WACC | B26: = (Peso Deuda x Kd post-ISR) + (Peso Capital x Ke) | C26: Wd, Kd post-ISR, We, Ke | D26: =D24*D22+D25*D23 -> 0.15242254
A27: 4. Cálculo de EVA
A28: ROIC | B28: = NOPAT / Capital Invertido | C28: NOPAT, Capital Invertido | D28: =D12/D17 -> 0.14528302
A29: Cargo de Capital | B29: = Capital Invertido x WACC | C29: Capital Invertido, WACC | D29: =D17*D26 -> 403919.72
A30: EVA Actual | B30: = NOPAT - Cargo de Capital | C30: NOPAT, Cargo de Capital | D30: =D12-D29 -> -18919.718
A31: EVA Proyectado | B31: = EVA Actual x (1 + Factor Mejora EVA Proyectado) | C31: EVA Actual, Factor Mejora | D31: =D30*(1+'02_Variables_Entrada'!C32) -> -20811.69
A32: Margen EVA | B32: = EVA Actual / Ventas | C32: EVA Actual, Ventas | D32: =D30/D5 -> -0.0037839437
A33: 5. Cálculo de Z-Score de Altman
A34: Capital de Trabajo | B34: = Activos Corrientes - Pasivos Corrientes | C34: Caja, CxC, Inventarios, Otros Activos Corrientes, Proveedores, Deuda CP, Otros Pasivos Operativos | D34: =('02_Variables_Entrada'!C14+'02_Variables_Entrada'!C15+'02_Variables_Entrada'!C16+'02_Variables_Entrada'!C17)-('02_Variables_Entrada'!C19+'02_Variables_Entrada'!C20+'02_Variables_Entrada'!C22) -> 900000
A35: Total Activos | B35: = Caja + CxC + Inventarios + Otros Activos Corrientes + Activos Fijos Netos | C35: Activos del balance | D35: =SUM('02_Variables_Entrada'!C14:C18) -> 3800000
A36: EBIT para Z-Score | B36: = EBIT | C36: EBIT | D36: =D10 -> 550000
A37: Ventas para Z-Score | B37: = Ventas | C37: Ventas | D37: =D5 -> 5000000
A38: Valor Contable del Capital | B38: = Capital Contable | C38: Capital Contable | D38: =D20 -> 2300000
A39: Pasivos Totales | B39: = Pasivos Operativos + Deuda CP + Deuda LP | C39: Proveedores, deuda, otros pasivos | D39: ='02_Variables_Entrada'!C19+'02_Variables_Entrada'!C20+'02_Variables_Entrada'!C21+'02_Variables_Entrada'!C22 -> 2000000
A40: X1: Capital de Trabajo / Total Activos | B40: = Capital de Trabajo / Total Activos | C40: Capital de Trabajo, Total Activos | D40: =D34/D35 -> 0.23684211
A41: X2: Utilidades Retenidas / Total Activos | B41: = Utilidades Retenidas / Total Activos | C41: Utilidades Retenidas, Total Activos | D41: ='02_Variables_Entrada'!C24/D35 -> 0.15789474
...

Sheet 04_Plan_Accion_Estrategias
A1: 04_Plan_Accion_Estrategias | Estrategias activadas por el motor
A3: Pilar | B3: Nivel de Prioridad | C3: Alerta Detonante | D3: Estrategia Recomendada | E3: KPI de Medición
A4: Rentabilidad | B4: Alta | C4: EVA Actual negativo o ROIC < WACC | D4: Priorizar iniciativas con impacto directo en NOPAT: ajuste de precios, renegociación de costos variables, depuración de líneas no rentables y revisión de gastos operativos por centro de costo. | E4: EVA mensual; Spread ROIC-WACC; Margen EBIT
A5: Rentabilidad | B5: Media | C5: Margen EBITDA bajo vs objetivo interno | D5: Rediseñar mix de productos/servicios y establecer tablero semanal de margen por unidad económica para detectar fugas de rentabilidad. | E5: Margen EBITDA; Margen bruto; % gastos operativos/ventas
A6: Liquidez | B6: Alta | C6: Razón Corriente < 1.0 o Prueba Ácida < 0.8 | D6: Implementar plan de caja de 13 semanas, priorizar cobranza vencida y congelar desembolsos no críticos hasta estabilizar liquidez operativa. | E6: Caja disponible; Razón corriente; Prueba ácida
A7: Liquidez | B7: Media | C7: Ciclo de Conversión de Efectivo alto | D7: Reducir DSO mediante política de crédito, descuentos por pronto pago y seguimiento de cobranza; optimizar DIO con niveles mínimos/máximos de inventario. | E7: CCC; DSO; DIO; DPO
A8: Estructura | B8: Alta | C8: Z-Score en zona de riesgo | D8: Reestructurar pasivos de corto plazo, renegociar vencimientos y evaluar capitalización o aportaciones para reducir presión financiera. | E8: Z-Score; Deuda/Capital; Cobertura de intereses
A9: Estructura | B9: Media | C9: Peso de deuda elevado en WACC | D9: Calcular costo financiero real por acreedor y sustituir deuda cara por fuentes más baratas o plazos compatibles con el ciclo operativo. | E9: Kd promedio; WACC; Peso deuda
A10: Rentabilidad | B10: Baja | C10: EVA positivo con oportunidad de expansión | D10: Reinvertir únicamente en proyectos con ROIC esperado superior al WACC y con hitos de seguimiento trimestral. | E10: ROIC incremental; EVA proyectado; Payback operativo
A11: Liquidez | B11: Baja | C11: Liquidez sana, pero capital atrapado en inventarios | D11: Implementar rotación ABC y liquidación ordenada de inventarios lentos sin erosionar margen estratégico. | E11: Rotación de inventario; DIO; margen por liquidación
